Traceback (most recent call last):
  File "/usr/share/miniconda3/envs/jupyter/lib/python3.7/site-packages/nbclient/client.py", line 622, in _async_poll_for_reply
    msg = await ensure_async(self.kc.shell_channel.get_msg(timeout=new_timeout))
  File "/usr/share/miniconda3/envs/jupyter/lib/python3.7/site-packages/nbclient/util.py", line 85, in ensure_async
    result = await obj
  File "/usr/share/miniconda3/envs/jupyter/lib/python3.7/site-packages/jupyter_client/asynchronous/channels.py", line 48, in get_msg
    raise Empty
_queue.Empty

During handling of the above exception, another exception occurred:

Traceback (most recent call last):
  File "/usr/share/miniconda3/envs/jupyter/lib/python3.7/site-packages/jupyter_cache/executors/utils.py", line 56, in single_nb_execution
    record_timing=False,
  File "/usr/share/miniconda3/envs/jupyter/lib/python3.7/site-packages/nbclient/client.py", line 1112, in execute
    return NotebookClient(nb=nb, resources=resources, km=km, **kwargs).execute()
  File "/usr/share/miniconda3/envs/jupyter/lib/python3.7/site-packages/nbclient/util.py", line 74, in wrapped
    return just_run(coro(*args, **kwargs))
  File "/usr/share/miniconda3/envs/jupyter/lib/python3.7/site-packages/nbclient/util.py", line 53, in just_run
    return loop.run_until_complete(coro)
  File "/usr/share/miniconda3/envs/jupyter/lib/python3.7/asyncio/base_events.py", line 587, in run_until_complete
    return future.result()
  File "/usr/share/miniconda3/envs/jupyter/lib/python3.7/site-packages/nbclient/client.py", line 554, in async_execute
    cell, index, execution_count=self.code_cells_executed + 1
  File "/usr/share/miniconda3/envs/jupyter/lib/python3.7/site-packages/nbclient/client.py", line 841, in async_execute_cell
    exec_reply = await self.task_poll_for_reply
  File "/usr/share/miniconda3/envs/jupyter/lib/python3.7/site-packages/nbclient/client.py", line 646, in _async_poll_for_reply
    await self._async_handle_timeout(timeout, cell)
  File "/usr/share/miniconda3/envs/jupyter/lib/python3.7/site-packages/nbclient/client.py", line 697, in _async_handle_timeout
    "Cell execution timed out", timeout, cell
nbclient.exceptions.CellTimeoutError: A cell timed out while it was being executed, after 30 seconds.
The message was: Cell execution timed out.
Here is a preview of the cell contents:
-------------------
from cloudstor import cloudstor
teaching_data = cloudstor(url="L93TxcmtLQzcfbk", password='')

teaching_data.download_file_if_distinct("BlueMarbleNG-TB_2004-12-01_rgb_3600x1800.TIFF", "Resources/BlueMarbleNG-TB_2004-12-01_rgb_3600x1800.TIFF")
teaching_data.download_file_if_distinct("color_etopo1_ice_low.tif", "Resources/color_etopo1_ice_low.tif")
teaching_data.download_file_if_distinct("EMAG2_image_V2_no_compr.tif", "Resources/EMAG2_image_V2_no_compr.tif")
teaching_data.download_file_if_distinct("global_age_data.3.6.z.npz", "Resources/global_age_data.3.6.z.npz")
teaching_data.download_file_if_distinct("etopo1_grayscale_hillshade.tif", "Resources/etopo1_grayscale_hillshade.tif")

teaching_data.download_directory("EQs","Resources/EQs")
-------------------

